<?xml version="1.0"?>
<robot name="test_robot">
    <link name="base_link">
        <visual>
            <geometry>
                <box size="0.2 0.2 0.1"/>
            </geometry>
            <material name="blue">
                <color rgba="0 0 0.8 1"/>
            </material>
        </visual>
        <collision>
            <geometry>
                <box size="0.2 0.2 0.1"/>
            </geometry>
        </collision>
        <inertial>
            <mass value="1.0"/>
            <inertia ixx="0.1" ixy="0" ixz="0" iyy="0.1" iyz="0" izz="0.1"/>
        </inertial>
    </link>

    <link name="link1">
        <visual>
            <geometry>
                <box size="0.1 0.1 0.2"/>
            </geometry>
            <material name="red">
                <color rgba="0.8 0 0 1"/>
            </material>
        </visual>
        <collision>
            <geometry>
                <box size="0.1 0.1 0.2"/>
            </geometry>
        </collision>
        <inertial>
            <mass value="0.5"/>
            <inertia ixx="0.05" ixy="0" ixz="0" iyy="0.05" iyz="0" izz="0.05"/>
        </inertial>
    </link>

    <link name="link2">
        <visual>
            <geometry>
                <box size="0.1 0.1 0.2"/>
            </geometry>
            <material name="green">
                <color rgba="0 0.8 0 1"/>
            </material>
        </visual>
        <collision>
            <geometry>
                <box size="0.1 0.1 0.2"/>
            </geometry>
        </collision>
        <inertial>
            <mass value="0.5"/>
            <inertia ixx="0.05" ixy="0" ixz="0" iyy="0.05" iyz="0" izz="0.05"/>
        </inertial>
    </link>

    <joint name="joint1" type="revolute">
        <parent link="base_link"/>
        <child link="link1"/>
        <origin xyz="0.15 0 0.05" rpy="0 0 0"/>
        <axis xyz="0 0 1"/>
        <limit lower="-3.14" upper="3.14" effort="10" velocity="1"/>
    </joint>

    <joint name="joint2" type="revolute">
        <parent link="link1"/>
        <child link="link2"/>
        <origin xyz="0.1 0 0.1" rpy="0 0 0"/>
        <axis xyz="0 0 1"/>
        <limit lower="-3.14" upper="3.14" effort="10" velocity="1"/>
    </joint>
</robot> 